[2023-08-21 14:36:26,323] {taskinstance.py:1179} INFO - Dependencies all met for <TaskInstance: Products_ETL.get_data manual__2023-08-21T14:28:27.273133+00:00 [queued]>
[2023-08-21 14:36:26,332] {taskinstance.py:1179} INFO - Dependencies all met for <TaskInstance: Products_ETL.get_data manual__2023-08-21T14:28:27.273133+00:00 [queued]>
[2023-08-21 14:36:26,334] {taskinstance.py:1376} INFO - 
--------------------------------------------------------------------------------
[2023-08-21 14:36:26,335] {taskinstance.py:1377} INFO - Starting attempt 3 of 6
[2023-08-21 14:36:26,349] {taskinstance.py:1378} INFO - 
--------------------------------------------------------------------------------
[2023-08-21 14:36:26,394] {taskinstance.py:1397} INFO - Executing <Task(PythonOperator): get_data> on 2023-08-21 14:28:27.273133+00:00
[2023-08-21 14:36:26,430] {standard_task_runner.py:52} INFO - Started process 404 to run task
[2023-08-21 14:36:26,453] {standard_task_runner.py:79} INFO - Running: ['***', 'tasks', 'run', 'Products_ETL', 'get_data', 'manual__2023-08-21T14:28:27.273133+00:00', '--job-id', '53', '--raw', '--subdir', 'DAGS_FOLDER/etl.py', '--cfg-path', '/tmp/tmptkn_21z6', '--error-file', '/tmp/tmp_k765mdz']
[2023-08-21 14:36:26,459] {standard_task_runner.py:80} INFO - Job 53: Subtask get_data
[2023-08-21 14:36:26,798] {task_command.py:371} INFO - Running <TaskInstance: Products_ETL.get_data manual__2023-08-21T14:28:27.273133+00:00 [running]> on host 0110d0e687e9
[2023-08-21 14:36:27,005] {taskinstance.py:1591} INFO - Exporting the following env vars:
AIRFLOW_CTX_DAG_OWNER=Sol
AIRFLOW_CTX_DAG_ID=Products_ETL
AIRFLOW_CTX_TASK_ID=get_data
AIRFLOW_CTX_EXECUTION_DATE=2023-08-21T14:28:27.273133+00:00
AIRFLOW_CTX_TRY_NUMBER=3
AIRFLOW_CTX_DAG_RUN_ID=manual__2023-08-21T14:28:27.273133+00:00
[2023-08-21 14:36:27,010] {taskinstance.py:1909} ERROR - Task failed with exception
Traceback (most recent call last):
  File "/home/airflow/.local/lib/python3.7/site-packages/airflow/operators/python.py", line 171, in execute
    return_value = self.execute_callable()
  File "/home/airflow/.local/lib/python3.7/site-packages/airflow/operators/python.py", line 189, in execute_callable
    return self.python_callable(*self.op_args, **self.op_kwargs)
TypeError: get_and_transform_Data() missing 1 required positional argument: 'pages'
[2023-08-21 14:36:27,039] {taskinstance.py:1420} INFO - Marking task as UP_FOR_RETRY. dag_id=Products_ETL, task_id=get_data, execution_date=20230821T142827, start_date=20230821T143626, end_date=20230821T143627
[2023-08-21 14:36:27,145] {standard_task_runner.py:97} ERROR - Failed to execute job 53 for task get_data (get_and_transform_Data() missing 1 required positional argument: 'pages'; 404)
[2023-08-21 14:36:27,310] {local_task_job.py:156} INFO - Task exited with return code 1
[2023-08-21 14:36:27,545] {local_task_job.py:273} INFO - 0 downstream tasks scheduled from follow-on schedule check
