[2023-08-22 14:32:27,271] {taskinstance.py:1179} INFO - Dependencies all met for <TaskInstance: new_etl.transformar_data manual__2023-08-22T14:32:22.842769+00:00 [queued]>
[2023-08-22 14:32:27,278] {taskinstance.py:1179} INFO - Dependencies all met for <TaskInstance: new_etl.transformar_data manual__2023-08-22T14:32:22.842769+00:00 [queued]>
[2023-08-22 14:32:27,279] {taskinstance.py:1376} INFO - 
--------------------------------------------------------------------------------
[2023-08-22 14:32:27,279] {taskinstance.py:1377} INFO - Starting attempt 1 of 4
[2023-08-22 14:32:27,280] {taskinstance.py:1378} INFO - 
--------------------------------------------------------------------------------
[2023-08-22 14:32:27,290] {taskinstance.py:1397} INFO - Executing <Task(PythonOperator): transformar_data> on 2023-08-22 14:32:22.842769+00:00
[2023-08-22 14:32:27,298] {standard_task_runner.py:52} INFO - Started process 7254 to run task
[2023-08-22 14:32:27,301] {standard_task_runner.py:79} INFO - Running: ['***', 'tasks', 'run', 'new_etl', 'transformar_data', 'manual__2023-08-22T14:32:22.842769+00:00', '--job-id', '169', '--raw', '--subdir', 'DAGS_FOLDER/etl2.py', '--cfg-path', '/tmp/tmpor17oyln', '--error-file', '/tmp/tmpsy34k3ui']
[2023-08-22 14:32:27,302] {standard_task_runner.py:80} INFO - Job 169: Subtask transformar_data
[2023-08-22 14:32:27,375] {task_command.py:371} INFO - Running <TaskInstance: new_etl.transformar_data manual__2023-08-22T14:32:22.842769+00:00 [running]> on host 0110d0e687e9
[2023-08-22 14:32:27,431] {taskinstance.py:1591} INFO - Exporting the following env vars:
AIRFLOW_CTX_DAG_OWNER=Sol
AIRFLOW_CTX_DAG_ID=new_etl
AIRFLOW_CTX_TASK_ID=transformar_data
AIRFLOW_CTX_EXECUTION_DATE=2023-08-22T14:32:22.842769+00:00
AIRFLOW_CTX_TRY_NUMBER=1
AIRFLOW_CTX_DAG_RUN_ID=manual__2023-08-22T14:32:22.842769+00:00
[2023-08-22 14:32:27,433] {taskinstance.py:1909} ERROR - Task failed with exception
Traceback (most recent call last):
  File "/home/airflow/.local/lib/python3.7/site-packages/airflow/operators/python.py", line 171, in execute
    return_value = self.execute_callable()
  File "/home/airflow/.local/lib/python3.7/site-packages/airflow/operators/python.py", line 189, in execute_callable
    return self.python_callable(*self.op_args, **self.op_kwargs)
  File "/opt/airflow/dags/function_etl.py", line 48, in transformar_data
    with open(os.path.join("dags","raw_data","/data.json"), "r") as json_file:
FileNotFoundError: [Errno 2] No such file or directory: '/data.json'
[2023-08-22 14:32:27,442] {taskinstance.py:1420} INFO - Marking task as UP_FOR_RETRY. dag_id=new_etl, task_id=transformar_data, execution_date=20230822T143222, start_date=20230822T143227, end_date=20230822T143227
[2023-08-22 14:32:27,450] {standard_task_runner.py:97} ERROR - Failed to execute job 169 for task transformar_data ([Errno 2] No such file or directory: '/data.json'; 7254)
[2023-08-22 14:32:27,473] {local_task_job.py:156} INFO - Task exited with return code 1
[2023-08-22 14:32:27,510] {local_task_job.py:273} INFO - 0 downstream tasks scheduled from follow-on schedule check
