[2023-08-21 21:02:35,704] {taskinstance.py:1179} INFO - Dependencies all met for <TaskInstance: Products_ETL_v2.get_data manual__2023-08-21T21:02:29.905514+00:00 [queued]>
[2023-08-21 21:02:35,712] {taskinstance.py:1179} INFO - Dependencies all met for <TaskInstance: Products_ETL_v2.get_data manual__2023-08-21T21:02:29.905514+00:00 [queued]>
[2023-08-21 21:02:35,712] {taskinstance.py:1376} INFO - 
--------------------------------------------------------------------------------
[2023-08-21 21:02:35,713] {taskinstance.py:1377} INFO - Starting attempt 1 of 6
[2023-08-21 21:02:35,713] {taskinstance.py:1378} INFO - 
--------------------------------------------------------------------------------
[2023-08-21 21:02:35,724] {taskinstance.py:1397} INFO - Executing <Task(PythonOperator): get_data> on 2023-08-21 21:02:29.905514+00:00
[2023-08-21 21:02:35,734] {standard_task_runner.py:52} INFO - Started process 14231 to run task
[2023-08-21 21:02:35,738] {standard_task_runner.py:79} INFO - Running: ['***', 'tasks', 'run', 'Products_ETL_v2', 'get_data', 'manual__2023-08-21T21:02:29.905514+00:00', '--job-id', '87', '--raw', '--subdir', 'DAGS_FOLDER/myETL.py', '--cfg-path', '/tmp/tmpz46aukqn', '--error-file', '/tmp/tmpq2saonkh']
[2023-08-21 21:02:35,740] {standard_task_runner.py:80} INFO - Job 87: Subtask get_data
[2023-08-21 21:02:35,792] {task_command.py:371} INFO - Running <TaskInstance: Products_ETL_v2.get_data manual__2023-08-21T21:02:29.905514+00:00 [running]> on host 0110d0e687e9
[2023-08-21 21:02:35,842] {taskinstance.py:1591} INFO - Exporting the following env vars:
AIRFLOW_CTX_DAG_OWNER=Sol
AIRFLOW_CTX_DAG_ID=Products_ETL_v2
AIRFLOW_CTX_TASK_ID=get_data
AIRFLOW_CTX_EXECUTION_DATE=2023-08-21T21:02:29.905514+00:00
AIRFLOW_CTX_TRY_NUMBER=1
AIRFLOW_CTX_DAG_RUN_ID=manual__2023-08-21T21:02:29.905514+00:00
[2023-08-21 21:02:35,852] {taskinstance.py:1909} ERROR - Task failed with exception
Traceback (most recent call last):
  File "/home/airflow/.local/lib/python3.7/site-packages/airflow/operators/python.py", line 171, in execute
    return_value = self.execute_callable()
  File "/home/airflow/.local/lib/python3.7/site-packages/airflow/operators/python.py", line 189, in execute_callable
    return self.python_callable(*self.op_args, **self.op_kwargs)
  File "/opt/airflow/dags/myETL.py", line 53, in get_and_transform_data
    df = pd.json_normalize(products_flat, max_level=1, sep='_')
  File "/home/airflow/.local/lib/python3.7/site-packages/pandas/io/json/_normalize.py", line 438, in _json_normalize
    if any([isinstance(x, dict) for x in y.values()] for y in data):
  File "/home/airflow/.local/lib/python3.7/site-packages/pandas/io/json/_normalize.py", line 438, in <genexpr>
    if any([isinstance(x, dict) for x in y.values()] for y in data):
AttributeError: 'list' object has no attribute 'values'
[2023-08-21 21:02:35,861] {taskinstance.py:1420} INFO - Marking task as UP_FOR_RETRY. dag_id=Products_ETL_v2, task_id=get_data, execution_date=20230821T210229, start_date=20230821T210235, end_date=20230821T210235
[2023-08-21 21:02:35,868] {standard_task_runner.py:97} ERROR - Failed to execute job 87 for task get_data ('list' object has no attribute 'values'; 14231)
[2023-08-21 21:02:35,912] {local_task_job.py:156} INFO - Task exited with return code 1
[2023-08-21 21:02:35,959] {local_task_job.py:273} INFO - 0 downstream tasks scheduled from follow-on schedule check
