[2023-08-22 13:40:41,728] {taskinstance.py:1179} INFO - Dependencies all met for <TaskInstance: new_etl.extraer_data manual__2023-08-22T13:34:19.381785+00:00 [queued]>
[2023-08-22 13:40:41,739] {taskinstance.py:1179} INFO - Dependencies all met for <TaskInstance: new_etl.extraer_data manual__2023-08-22T13:34:19.381785+00:00 [queued]>
[2023-08-22 13:40:41,740] {taskinstance.py:1376} INFO - 
--------------------------------------------------------------------------------
[2023-08-22 13:40:41,742] {taskinstance.py:1377} INFO - Starting attempt 3 of 4
[2023-08-22 13:40:41,745] {taskinstance.py:1378} INFO - 
--------------------------------------------------------------------------------
[2023-08-22 13:40:41,772] {taskinstance.py:1397} INFO - Executing <Task(PythonOperator): extraer_data> on 2023-08-22 13:34:19.381785+00:00
[2023-08-22 13:40:41,789] {standard_task_runner.py:52} INFO - Started process 673 to run task
[2023-08-22 13:40:41,798] {standard_task_runner.py:79} INFO - Running: ['***', 'tasks', 'run', 'new_etl', 'extraer_data', 'manual__2023-08-22T13:34:19.381785+00:00', '--job-id', '134', '--raw', '--subdir', 'DAGS_FOLDER/etl2.py', '--cfg-path', '/tmp/tmpdw_feimz', '--error-file', '/tmp/tmpftni792q']
[2023-08-22 13:40:41,800] {standard_task_runner.py:80} INFO - Job 134: Subtask extraer_data
[2023-08-22 13:40:41,881] {task_command.py:371} INFO - Running <TaskInstance: new_etl.extraer_data manual__2023-08-22T13:34:19.381785+00:00 [running]> on host 0110d0e687e9
[2023-08-22 13:40:41,956] {taskinstance.py:1591} INFO - Exporting the following env vars:
AIRFLOW_CTX_DAG_OWNER=Sol
AIRFLOW_CTX_DAG_ID=new_etl
AIRFLOW_CTX_TASK_ID=extraer_data
AIRFLOW_CTX_EXECUTION_DATE=2023-08-22T13:34:19.381785+00:00
AIRFLOW_CTX_TRY_NUMBER=3
AIRFLOW_CTX_DAG_RUN_ID=manual__2023-08-22T13:34:19.381785+00:00
[2023-08-22 13:40:45,677] {taskinstance.py:1909} ERROR - Task failed with exception
Traceback (most recent call last):
  File "/home/airflow/.local/lib/python3.7/site-packages/airflow/operators/python.py", line 171, in execute
    return_value = self.execute_callable()
  File "/home/airflow/.local/lib/python3.7/site-packages/airflow/operators/python.py", line 189, in execute_callable
    return self.python_callable(*self.op_args, **self.op_kwargs)
  File "/opt/airflow/dags/function_etl.py", line 43, in extraer_data
    with open(dag_path+'/raw_data/'+"data.json", "w") as json_file:
FileNotFoundError: [Errno 2] No such file or directory: '/opt/airflow/raw_data/data.json'
[2023-08-22 13:40:45,698] {taskinstance.py:1420} INFO - Marking task as UP_FOR_RETRY. dag_id=new_etl, task_id=extraer_data, execution_date=20230822T133419, start_date=20230822T134041, end_date=20230822T134045
[2023-08-22 13:40:45,712] {standard_task_runner.py:97} ERROR - Failed to execute job 134 for task extraer_data ([Errno 2] No such file or directory: '/opt/airflow/raw_data/data.json'; 673)
[2023-08-22 13:40:45,728] {local_task_job.py:156} INFO - Task exited with return code 1
[2023-08-22 13:40:45,792] {local_task_job.py:273} INFO - 0 downstream tasks scheduled from follow-on schedule check
