[2023-08-21 14:28:43,494] {taskinstance.py:1179} INFO - Dependencies all met for <TaskInstance: Products_ETL.get_data manual__2023-08-18T20:04:09.740595+00:00 [queued]>
[2023-08-21 14:28:43,511] {taskinstance.py:1179} INFO - Dependencies all met for <TaskInstance: Products_ETL.get_data manual__2023-08-18T20:04:09.740595+00:00 [queued]>
[2023-08-21 14:28:43,514] {taskinstance.py:1376} INFO - 
--------------------------------------------------------------------------------
[2023-08-21 14:28:43,515] {taskinstance.py:1377} INFO - Starting attempt 5 of 6
[2023-08-21 14:28:43,527] {taskinstance.py:1378} INFO - 
--------------------------------------------------------------------------------
[2023-08-21 14:28:43,547] {taskinstance.py:1397} INFO - Executing <Task(PythonOperator): get_data> on 2023-08-18 20:04:09.740595+00:00
[2023-08-21 14:28:43,562] {standard_task_runner.py:52} INFO - Started process 273 to run task
[2023-08-21 14:28:43,584] {standard_task_runner.py:79} INFO - Running: ['***', 'tasks', 'run', 'Products_ETL', 'get_data', 'manual__2023-08-18T20:04:09.740595+00:00', '--job-id', '36', '--raw', '--subdir', 'DAGS_FOLDER/etl.py', '--cfg-path', '/tmp/tmp5bshch55', '--error-file', '/tmp/tmpykyddrh6']
[2023-08-21 14:28:43,586] {standard_task_runner.py:80} INFO - Job 36: Subtask get_data
[2023-08-21 14:28:43,796] {task_command.py:371} INFO - Running <TaskInstance: Products_ETL.get_data manual__2023-08-18T20:04:09.740595+00:00 [running]> on host 0110d0e687e9
[2023-08-21 14:28:43,956] {taskinstance.py:1591} INFO - Exporting the following env vars:
AIRFLOW_CTX_DAG_OWNER=Sol
AIRFLOW_CTX_DAG_ID=Products_ETL
AIRFLOW_CTX_TASK_ID=get_data
AIRFLOW_CTX_EXECUTION_DATE=2023-08-18T20:04:09.740595+00:00
AIRFLOW_CTX_TRY_NUMBER=5
AIRFLOW_CTX_DAG_RUN_ID=manual__2023-08-18T20:04:09.740595+00:00
[2023-08-21 14:28:43,961] {taskinstance.py:1909} ERROR - Task failed with exception
Traceback (most recent call last):
  File "/home/airflow/.local/lib/python3.7/site-packages/airflow/operators/python.py", line 171, in execute
    return_value = self.execute_callable()
  File "/home/airflow/.local/lib/python3.7/site-packages/airflow/operators/python.py", line 189, in execute_callable
    return self.python_callable(*self.op_args, **self.op_kwargs)
TypeError: get_and_transform_Data() missing 1 required positional argument: 'pages'
[2023-08-21 14:28:43,969] {taskinstance.py:1420} INFO - Marking task as UP_FOR_RETRY. dag_id=Products_ETL, task_id=get_data, execution_date=20230818T200409, start_date=20230821T142843, end_date=20230821T142843
[2023-08-21 14:28:43,986] {standard_task_runner.py:97} ERROR - Failed to execute job 36 for task get_data (get_and_transform_Data() missing 1 required positional argument: 'pages'; 273)
[2023-08-21 14:28:44,030] {local_task_job.py:156} INFO - Task exited with return code 1
[2023-08-21 14:28:44,101] {dagrun.py:1081} ERROR - Failed to get task '<TaskInstance: Products_ETL.get_number_pages manual__2023-08-18T20:04:09.740595+00:00 [removed]>' for dag 'Products_ETL'. Marking it as removed.
[2023-08-21 14:28:44,124] {local_task_job.py:273} INFO - 0 downstream tasks scheduled from follow-on schedule check
