[2023-08-21 21:07:58,850] {taskinstance.py:1179} INFO - Dependencies all met for <TaskInstance: Products_ETL_v2.get_data manual__2023-08-21T20:52:46.615113+00:00 [queued]>
[2023-08-21 21:07:58,856] {taskinstance.py:1179} INFO - Dependencies all met for <TaskInstance: Products_ETL_v2.get_data manual__2023-08-21T20:52:46.615113+00:00 [queued]>
[2023-08-21 21:07:58,857] {taskinstance.py:1376} INFO - 
--------------------------------------------------------------------------------
[2023-08-21 21:07:58,858] {taskinstance.py:1377} INFO - Starting attempt 6 of 6
[2023-08-21 21:07:58,858] {taskinstance.py:1378} INFO - 
--------------------------------------------------------------------------------
[2023-08-21 21:07:58,867] {taskinstance.py:1397} INFO - Executing <Task(PythonOperator): get_data> on 2023-08-21 20:52:46.615113+00:00
[2023-08-21 21:07:58,872] {standard_task_runner.py:52} INFO - Started process 14743 to run task
[2023-08-21 21:07:58,876] {standard_task_runner.py:79} INFO - Running: ['***', 'tasks', 'run', 'Products_ETL_v2', 'get_data', 'manual__2023-08-21T20:52:46.615113+00:00', '--job-id', '92', '--raw', '--subdir', 'DAGS_FOLDER/myETL.py', '--cfg-path', '/tmp/tmps01ltjz9', '--error-file', '/tmp/tmpzit31vph']
[2023-08-21 21:07:58,877] {standard_task_runner.py:80} INFO - Job 92: Subtask get_data
[2023-08-21 21:07:58,934] {task_command.py:371} INFO - Running <TaskInstance: Products_ETL_v2.get_data manual__2023-08-21T20:52:46.615113+00:00 [running]> on host 0110d0e687e9
[2023-08-21 21:07:59,016] {taskinstance.py:1591} INFO - Exporting the following env vars:
AIRFLOW_CTX_DAG_OWNER=Sol
AIRFLOW_CTX_DAG_ID=Products_ETL_v2
AIRFLOW_CTX_TASK_ID=get_data
AIRFLOW_CTX_EXECUTION_DATE=2023-08-21T20:52:46.615113+00:00
AIRFLOW_CTX_TRY_NUMBER=6
AIRFLOW_CTX_DAG_RUN_ID=manual__2023-08-21T20:52:46.615113+00:00
[2023-08-21 21:07:59,029] {taskinstance.py:1909} ERROR - Task failed with exception
Traceback (most recent call last):
  File "/home/airflow/.local/lib/python3.7/site-packages/airflow/operators/python.py", line 171, in execute
    return_value = self.execute_callable()
  File "/home/airflow/.local/lib/python3.7/site-packages/airflow/operators/python.py", line 189, in execute_callable
    return self.python_callable(*self.op_args, **self.op_kwargs)
  File "/opt/airflow/dags/myETL.py", line 53, in get_and_transform_data
    df = pd.json_normalize(products_flat, max_level=1, sep='_')
  File "/home/airflow/.local/lib/python3.7/site-packages/pandas/io/json/_normalize.py", line 438, in _json_normalize
    if any([isinstance(x, dict) for x in y.values()] for y in data):
  File "/home/airflow/.local/lib/python3.7/site-packages/pandas/io/json/_normalize.py", line 438, in <genexpr>
    if any([isinstance(x, dict) for x in y.values()] for y in data):
AttributeError: 'list' object has no attribute 'values'
[2023-08-21 21:07:59,038] {taskinstance.py:1420} INFO - Marking task as FAILED. dag_id=Products_ETL_v2, task_id=get_data, execution_date=20230821T205246, start_date=20230821T210758, end_date=20230821T210759
[2023-08-21 21:07:59,045] {standard_task_runner.py:97} ERROR - Failed to execute job 92 for task get_data ('list' object has no attribute 'values'; 14743)
[2023-08-21 21:07:59,091] {local_task_job.py:156} INFO - Task exited with return code 1
[2023-08-21 21:07:59,121] {local_task_job.py:273} INFO - 0 downstream tasks scheduled from follow-on schedule check
