[2023-08-21 21:04:57,000] {taskinstance.py:1179} INFO - Dependencies all met for <TaskInstance: Products_ETL_v2.get_data manual__2023-08-21T20:52:46.615113+00:00 [queued]>
[2023-08-21 21:04:57,010] {taskinstance.py:1179} INFO - Dependencies all met for <TaskInstance: Products_ETL_v2.get_data manual__2023-08-21T20:52:46.615113+00:00 [queued]>
[2023-08-21 21:04:57,012] {taskinstance.py:1376} INFO - 
--------------------------------------------------------------------------------
[2023-08-21 21:04:57,012] {taskinstance.py:1377} INFO - Starting attempt 5 of 6
[2023-08-21 21:04:57,013] {taskinstance.py:1378} INFO - 
--------------------------------------------------------------------------------
[2023-08-21 21:04:57,023] {taskinstance.py:1397} INFO - Executing <Task(PythonOperator): get_data> on 2023-08-21 20:52:46.615113+00:00
[2023-08-21 21:04:57,034] {standard_task_runner.py:52} INFO - Started process 14457 to run task
[2023-08-21 21:04:57,037] {standard_task_runner.py:79} INFO - Running: ['***', 'tasks', 'run', 'Products_ETL_v2', 'get_data', 'manual__2023-08-21T20:52:46.615113+00:00', '--job-id', '89', '--raw', '--subdir', 'DAGS_FOLDER/myETL.py', '--cfg-path', '/tmp/tmpzj5ailql', '--error-file', '/tmp/tmp97tia21p']
[2023-08-21 21:04:57,039] {standard_task_runner.py:80} INFO - Job 89: Subtask get_data
[2023-08-21 21:04:57,093] {task_command.py:371} INFO - Running <TaskInstance: Products_ETL_v2.get_data manual__2023-08-21T20:52:46.615113+00:00 [running]> on host 0110d0e687e9
[2023-08-21 21:04:57,142] {taskinstance.py:1591} INFO - Exporting the following env vars:
AIRFLOW_CTX_DAG_OWNER=Sol
AIRFLOW_CTX_DAG_ID=Products_ETL_v2
AIRFLOW_CTX_TASK_ID=get_data
AIRFLOW_CTX_EXECUTION_DATE=2023-08-21T20:52:46.615113+00:00
AIRFLOW_CTX_TRY_NUMBER=5
AIRFLOW_CTX_DAG_RUN_ID=manual__2023-08-21T20:52:46.615113+00:00
[2023-08-21 21:04:57,155] {taskinstance.py:1909} ERROR - Task failed with exception
Traceback (most recent call last):
  File "/home/airflow/.local/lib/python3.7/site-packages/airflow/operators/python.py", line 171, in execute
    return_value = self.execute_callable()
  File "/home/airflow/.local/lib/python3.7/site-packages/airflow/operators/python.py", line 189, in execute_callable
    return self.python_callable(*self.op_args, **self.op_kwargs)
  File "/opt/airflow/dags/myETL.py", line 53, in get_and_transform_data
    df = pd.json_normalize(products_flat, max_level=1, sep='_')
  File "/home/airflow/.local/lib/python3.7/site-packages/pandas/io/json/_normalize.py", line 438, in _json_normalize
    if any([isinstance(x, dict) for x in y.values()] for y in data):
  File "/home/airflow/.local/lib/python3.7/site-packages/pandas/io/json/_normalize.py", line 438, in <genexpr>
    if any([isinstance(x, dict) for x in y.values()] for y in data):
AttributeError: 'list' object has no attribute 'values'
[2023-08-21 21:04:57,169] {taskinstance.py:1420} INFO - Marking task as UP_FOR_RETRY. dag_id=Products_ETL_v2, task_id=get_data, execution_date=20230821T205246, start_date=20230821T210457, end_date=20230821T210457
[2023-08-21 21:04:57,176] {standard_task_runner.py:97} ERROR - Failed to execute job 89 for task get_data ('list' object has no attribute 'values'; 14457)
[2023-08-21 21:04:57,213] {local_task_job.py:156} INFO - Task exited with return code 1
[2023-08-21 21:04:57,241] {local_task_job.py:273} INFO - 0 downstream tasks scheduled from follow-on schedule check
