[2023-08-21 20:52:51,271] {taskinstance.py:1179} INFO - Dependencies all met for <TaskInstance: Products_ETL_v2.get_data manual__2023-08-21T20:52:46.615113+00:00 [queued]>
[2023-08-21 20:52:51,276] {taskinstance.py:1179} INFO - Dependencies all met for <TaskInstance: Products_ETL_v2.get_data manual__2023-08-21T20:52:46.615113+00:00 [queued]>
[2023-08-21 20:52:51,277] {taskinstance.py:1376} INFO - 
--------------------------------------------------------------------------------
[2023-08-21 20:52:51,278] {taskinstance.py:1377} INFO - Starting attempt 1 of 6
[2023-08-21 20:52:51,278] {taskinstance.py:1378} INFO - 
--------------------------------------------------------------------------------
[2023-08-21 20:52:51,286] {taskinstance.py:1397} INFO - Executing <Task(PythonOperator): get_data> on 2023-08-21 20:52:46.615113+00:00
[2023-08-21 20:52:51,292] {standard_task_runner.py:52} INFO - Started process 13267 to run task
[2023-08-21 20:52:51,295] {standard_task_runner.py:79} INFO - Running: ['***', 'tasks', 'run', 'Products_ETL_v2', 'get_data', 'manual__2023-08-21T20:52:46.615113+00:00', '--job-id', '73', '--raw', '--subdir', 'DAGS_FOLDER/myETL.py', '--cfg-path', '/tmp/tmpwz3aunh5', '--error-file', '/tmp/tmpoh3snnqi']
[2023-08-21 20:52:51,297] {standard_task_runner.py:80} INFO - Job 73: Subtask get_data
[2023-08-21 20:52:51,368] {task_command.py:371} INFO - Running <TaskInstance: Products_ETL_v2.get_data manual__2023-08-21T20:52:46.615113+00:00 [running]> on host 0110d0e687e9
[2023-08-21 20:52:51,419] {taskinstance.py:1591} INFO - Exporting the following env vars:
AIRFLOW_CTX_DAG_OWNER=Sol
AIRFLOW_CTX_DAG_ID=Products_ETL_v2
AIRFLOW_CTX_TASK_ID=get_data
AIRFLOW_CTX_EXECUTION_DATE=2023-08-21T20:52:46.615113+00:00
AIRFLOW_CTX_TRY_NUMBER=1
AIRFLOW_CTX_DAG_RUN_ID=manual__2023-08-21T20:52:46.615113+00:00
[2023-08-21 20:52:51,421] {taskinstance.py:1909} ERROR - Task failed with exception
Traceback (most recent call last):
  File "/home/airflow/.local/lib/python3.7/site-packages/airflow/operators/python.py", line 171, in execute
    return_value = self.execute_callable()
  File "/home/airflow/.local/lib/python3.7/site-packages/airflow/operators/python.py", line 189, in execute_callable
    return self.python_callable(*self.op_args, **self.op_kwargs)
  File "/opt/airflow/dags/myETL.py", line 51, in get_and_transform_data
    data = ti.xcom_pull(key='api_call', task_ids=['api_call'])
TypeError: xcom_pull() missing 1 required positional argument: 'context'
[2023-08-21 20:52:51,431] {taskinstance.py:1420} INFO - Marking task as UP_FOR_RETRY. dag_id=Products_ETL_v2, task_id=get_data, execution_date=20230821T205246, start_date=20230821T205251, end_date=20230821T205251
[2023-08-21 20:52:51,438] {standard_task_runner.py:97} ERROR - Failed to execute job 73 for task get_data (xcom_pull() missing 1 required positional argument: 'context'; 13267)
[2023-08-21 20:52:51,469] {local_task_job.py:156} INFO - Task exited with return code 1
[2023-08-21 20:52:51,497] {local_task_job.py:273} INFO - 0 downstream tasks scheduled from follow-on schedule check
