[2023-08-21 15:03:52,771] {taskinstance.py:1179} INFO - Dependencies all met for <TaskInstance: Products_ETL_v2.get_data manual__2023-08-21T15:00:45.689440+00:00 [queued]>
[2023-08-21 15:03:52,778] {taskinstance.py:1179} INFO - Dependencies all met for <TaskInstance: Products_ETL_v2.get_data manual__2023-08-21T15:00:45.689440+00:00 [queued]>
[2023-08-21 15:03:52,779] {taskinstance.py:1376} INFO - 
--------------------------------------------------------------------------------
[2023-08-21 15:03:52,779] {taskinstance.py:1377} INFO - Starting attempt 2 of 6
[2023-08-21 15:03:52,780] {taskinstance.py:1378} INFO - 
--------------------------------------------------------------------------------
[2023-08-21 15:03:52,789] {taskinstance.py:1397} INFO - Executing <Task(PythonOperator): get_data> on 2023-08-21 15:00:45.689440+00:00
[2023-08-21 15:03:52,795] {standard_task_runner.py:52} INFO - Started process 2211 to run task
[2023-08-21 15:03:52,799] {standard_task_runner.py:79} INFO - Running: ['***', 'tasks', 'run', 'Products_ETL_v2', 'get_data', 'manual__2023-08-21T15:00:45.689440+00:00', '--job-id', '68', '--raw', '--subdir', 'DAGS_FOLDER/myETL.py', '--cfg-path', '/tmp/tmpn8vi2rwu', '--error-file', '/tmp/tmppqmqn9uy']
[2023-08-21 15:03:52,800] {standard_task_runner.py:80} INFO - Job 68: Subtask get_data
[2023-08-21 15:03:52,877] {task_command.py:371} INFO - Running <TaskInstance: Products_ETL_v2.get_data manual__2023-08-21T15:00:45.689440+00:00 [running]> on host 0110d0e687e9
[2023-08-21 15:03:52,953] {taskinstance.py:1591} INFO - Exporting the following env vars:
AIRFLOW_CTX_DAG_OWNER=Sol
AIRFLOW_CTX_DAG_ID=Products_ETL_v2
AIRFLOW_CTX_TASK_ID=get_data
AIRFLOW_CTX_EXECUTION_DATE=2023-08-21T15:00:45.689440+00:00
AIRFLOW_CTX_TRY_NUMBER=2
AIRFLOW_CTX_DAG_RUN_ID=manual__2023-08-21T15:00:45.689440+00:00
[2023-08-21 15:03:52,971] {taskinstance.py:1909} ERROR - Task failed with exception
Traceback (most recent call last):
  File "/home/airflow/.local/lib/python3.7/site-packages/airflow/operators/python.py", line 171, in execute
    return_value = self.execute_callable()
  File "/home/airflow/.local/lib/python3.7/site-packages/airflow/operators/python.py", line 189, in execute_callable
    return self.python_callable(*self.op_args, **self.op_kwargs)
  File "/opt/airflow/dags/myETL.py", line 55, in get_and_transform_data
    df = pd.json_normalize(products_flat, max_level=1, sep='_')
  File "/home/airflow/.local/lib/python3.7/site-packages/pandas/io/json/_normalize.py", line 438, in _json_normalize
    if any([isinstance(x, dict) for x in y.values()] for y in data):
  File "/home/airflow/.local/lib/python3.7/site-packages/pandas/io/json/_normalize.py", line 438, in <genexpr>
    if any([isinstance(x, dict) for x in y.values()] for y in data):
AttributeError: 'str' object has no attribute 'values'
[2023-08-21 15:03:52,982] {taskinstance.py:1420} INFO - Marking task as UP_FOR_RETRY. dag_id=Products_ETL_v2, task_id=get_data, execution_date=20230821T150045, start_date=20230821T150352, end_date=20230821T150352
[2023-08-21 15:03:52,994] {standard_task_runner.py:97} ERROR - Failed to execute job 68 for task get_data ('str' object has no attribute 'values'; 2211)
[2023-08-21 15:03:53,011] {local_task_job.py:156} INFO - Task exited with return code 1
[2023-08-21 15:03:53,063] {local_task_job.py:273} INFO - 0 downstream tasks scheduled from follow-on schedule check
