[2023-08-21 21:12:03,664] {taskinstance.py:1179} INFO - Dependencies all met for <TaskInstance: Products_ETL_v2.get_data manual__2023-08-21T20:54:45.854326+00:00 [queued]>
[2023-08-21 21:12:03,672] {taskinstance.py:1179} INFO - Dependencies all met for <TaskInstance: Products_ETL_v2.get_data manual__2023-08-21T20:54:45.854326+00:00 [queued]>
[2023-08-21 21:12:03,673] {taskinstance.py:1376} INFO - 
--------------------------------------------------------------------------------
[2023-08-21 21:12:03,674] {taskinstance.py:1377} INFO - Starting attempt 7 of 8
[2023-08-21 21:12:03,674] {taskinstance.py:1378} INFO - 
--------------------------------------------------------------------------------
[2023-08-21 21:12:03,685] {taskinstance.py:1397} INFO - Executing <Task(PythonOperator): get_data> on 2023-08-21 20:54:45.854326+00:00
[2023-08-21 21:12:03,694] {standard_task_runner.py:52} INFO - Started process 15154 to run task
[2023-08-21 21:12:03,698] {standard_task_runner.py:79} INFO - Running: ['***', 'tasks', 'run', 'Products_ETL_v2', 'get_data', 'manual__2023-08-21T20:54:45.854326+00:00', '--job-id', '99', '--raw', '--subdir', 'DAGS_FOLDER/myETL.py', '--cfg-path', '/tmp/tmpvylq24xn', '--error-file', '/tmp/tmplkwngpzi']
[2023-08-21 21:12:03,700] {standard_task_runner.py:80} INFO - Job 99: Subtask get_data
[2023-08-21 21:12:03,754] {task_command.py:371} INFO - Running <TaskInstance: Products_ETL_v2.get_data manual__2023-08-21T20:54:45.854326+00:00 [running]> on host 0110d0e687e9
[2023-08-21 21:12:03,801] {taskinstance.py:1591} INFO - Exporting the following env vars:
AIRFLOW_CTX_DAG_OWNER=Sol
AIRFLOW_CTX_DAG_ID=Products_ETL_v2
AIRFLOW_CTX_TASK_ID=get_data
AIRFLOW_CTX_EXECUTION_DATE=2023-08-21T20:54:45.854326+00:00
AIRFLOW_CTX_TRY_NUMBER=7
AIRFLOW_CTX_DAG_RUN_ID=manual__2023-08-21T20:54:45.854326+00:00
[2023-08-21 21:12:03,811] {taskinstance.py:1909} ERROR - Task failed with exception
Traceback (most recent call last):
  File "/home/airflow/.local/lib/python3.7/site-packages/airflow/operators/python.py", line 171, in execute
    return_value = self.execute_callable()
  File "/home/airflow/.local/lib/python3.7/site-packages/airflow/operators/python.py", line 189, in execute_callable
    return self.python_callable(*self.op_args, **self.op_kwargs)
  File "/opt/airflow/dags/myETL.py", line 53, in get_and_transform_data
    df = pd.json_normalize(products_flat, max_level=1, sep='_')
  File "/home/airflow/.local/lib/python3.7/site-packages/pandas/io/json/_normalize.py", line 438, in _json_normalize
    if any([isinstance(x, dict) for x in y.values()] for y in data):
  File "/home/airflow/.local/lib/python3.7/site-packages/pandas/io/json/_normalize.py", line 438, in <genexpr>
    if any([isinstance(x, dict) for x in y.values()] for y in data):
AttributeError: 'list' object has no attribute 'values'
[2023-08-21 21:12:03,821] {taskinstance.py:1420} INFO - Marking task as UP_FOR_RETRY. dag_id=Products_ETL_v2, task_id=get_data, execution_date=20230821T205445, start_date=20230821T211203, end_date=20230821T211203
[2023-08-21 21:12:03,828] {standard_task_runner.py:97} ERROR - Failed to execute job 99 for task get_data ('list' object has no attribute 'values'; 15154)
[2023-08-21 21:12:03,871] {local_task_job.py:156} INFO - Task exited with return code 1
[2023-08-21 21:12:03,900] {local_task_job.py:273} INFO - 0 downstream tasks scheduled from follow-on schedule check
