[2023-08-21 21:09:02,950] {taskinstance.py:1179} INFO - Dependencies all met for <TaskInstance: Products_ETL_v2.get_data manual__2023-08-21T20:54:45.854326+00:00 [queued]>
[2023-08-21 21:09:02,958] {taskinstance.py:1179} INFO - Dependencies all met for <TaskInstance: Products_ETL_v2.get_data manual__2023-08-21T20:54:45.854326+00:00 [queued]>
[2023-08-21 21:09:02,958] {taskinstance.py:1376} INFO - 
--------------------------------------------------------------------------------
[2023-08-21 21:09:02,959] {taskinstance.py:1377} INFO - Starting attempt 6 of 8
[2023-08-21 21:09:02,960] {taskinstance.py:1378} INFO - 
--------------------------------------------------------------------------------
[2023-08-21 21:09:02,970] {taskinstance.py:1397} INFO - Executing <Task(PythonOperator): get_data> on 2023-08-21 20:54:45.854326+00:00
[2023-08-21 21:09:02,977] {standard_task_runner.py:52} INFO - Started process 14857 to run task
[2023-08-21 21:09:02,980] {standard_task_runner.py:79} INFO - Running: ['***', 'tasks', 'run', 'Products_ETL_v2', 'get_data', 'manual__2023-08-21T20:54:45.854326+00:00', '--job-id', '96', '--raw', '--subdir', 'DAGS_FOLDER/myETL.py', '--cfg-path', '/tmp/tmp7fcekz1p', '--error-file', '/tmp/tmpc2pdugxi']
[2023-08-21 21:09:02,981] {standard_task_runner.py:80} INFO - Job 96: Subtask get_data
[2023-08-21 21:09:03,041] {task_command.py:371} INFO - Running <TaskInstance: Products_ETL_v2.get_data manual__2023-08-21T20:54:45.854326+00:00 [running]> on host 0110d0e687e9
[2023-08-21 21:09:03,098] {taskinstance.py:1591} INFO - Exporting the following env vars:
AIRFLOW_CTX_DAG_OWNER=Sol
AIRFLOW_CTX_DAG_ID=Products_ETL_v2
AIRFLOW_CTX_TASK_ID=get_data
AIRFLOW_CTX_EXECUTION_DATE=2023-08-21T20:54:45.854326+00:00
AIRFLOW_CTX_TRY_NUMBER=6
AIRFLOW_CTX_DAG_RUN_ID=manual__2023-08-21T20:54:45.854326+00:00
[2023-08-21 21:09:03,109] {taskinstance.py:1909} ERROR - Task failed with exception
Traceback (most recent call last):
  File "/home/airflow/.local/lib/python3.7/site-packages/airflow/operators/python.py", line 171, in execute
    return_value = self.execute_callable()
  File "/home/airflow/.local/lib/python3.7/site-packages/airflow/operators/python.py", line 189, in execute_callable
    return self.python_callable(*self.op_args, **self.op_kwargs)
  File "/opt/airflow/dags/myETL.py", line 53, in get_and_transform_data
    df = pd.json_normalize(products_flat, max_level=1, sep='_')
  File "/home/airflow/.local/lib/python3.7/site-packages/pandas/io/json/_normalize.py", line 438, in _json_normalize
    if any([isinstance(x, dict) for x in y.values()] for y in data):
  File "/home/airflow/.local/lib/python3.7/site-packages/pandas/io/json/_normalize.py", line 438, in <genexpr>
    if any([isinstance(x, dict) for x in y.values()] for y in data):
AttributeError: 'list' object has no attribute 'values'
[2023-08-21 21:09:03,118] {taskinstance.py:1420} INFO - Marking task as UP_FOR_RETRY. dag_id=Products_ETL_v2, task_id=get_data, execution_date=20230821T205445, start_date=20230821T210902, end_date=20230821T210903
[2023-08-21 21:09:03,125] {standard_task_runner.py:97} ERROR - Failed to execute job 96 for task get_data ('list' object has no attribute 'values'; 14857)
[2023-08-21 21:09:03,153] {local_task_job.py:156} INFO - Task exited with return code 1
[2023-08-21 21:09:03,186] {local_task_job.py:273} INFO - 0 downstream tasks scheduled from follow-on schedule check
