[2023-08-21 20:52:06,344] {taskinstance.py:1179} INFO - Dependencies all met for <TaskInstance: Products_ETL_v2.get_data scheduled__2023-08-20T00:00:00+00:00 [queued]>
[2023-08-21 20:52:06,356] {taskinstance.py:1179} INFO - Dependencies all met for <TaskInstance: Products_ETL_v2.get_data scheduled__2023-08-20T00:00:00+00:00 [queued]>
[2023-08-21 20:52:06,357] {taskinstance.py:1376} INFO - 
--------------------------------------------------------------------------------
[2023-08-21 20:52:06,357] {taskinstance.py:1377} INFO - Starting attempt 5 of 6
[2023-08-21 20:52:06,357] {taskinstance.py:1378} INFO - 
--------------------------------------------------------------------------------
[2023-08-21 20:52:06,383] {taskinstance.py:1397} INFO - Executing <Task(PythonOperator): get_data> on 2023-08-20 00:00:00+00:00
[2023-08-21 20:52:06,399] {standard_task_runner.py:52} INFO - Started process 13188 to run task
[2023-08-21 20:52:06,535] {standard_task_runner.py:79} INFO - Running: ['***', 'tasks', 'run', 'Products_ETL_v2', 'get_data', 'scheduled__2023-08-20T00:00:00+00:00', '--job-id', '71', '--raw', '--subdir', 'DAGS_FOLDER/myETL.py', '--cfg-path', '/tmp/tmphk79ub4o', '--error-file', '/tmp/tmph9rwu34t']
[2023-08-21 20:52:06,592] {standard_task_runner.py:80} INFO - Job 71: Subtask get_data
[2023-08-21 20:52:07,610] {task_command.py:371} INFO - Running <TaskInstance: Products_ETL_v2.get_data scheduled__2023-08-20T00:00:00+00:00 [running]> on host 0110d0e687e9
[2023-08-21 20:52:08,020] {taskinstance.py:1591} INFO - Exporting the following env vars:
AIRFLOW_CTX_DAG_OWNER=Sol
AIRFLOW_CTX_DAG_ID=Products_ETL_v2
AIRFLOW_CTX_TASK_ID=get_data
AIRFLOW_CTX_EXECUTION_DATE=2023-08-20T00:00:00+00:00
AIRFLOW_CTX_TRY_NUMBER=5
AIRFLOW_CTX_DAG_RUN_ID=scheduled__2023-08-20T00:00:00+00:00
[2023-08-21 20:52:08,027] {taskinstance.py:1909} ERROR - Task failed with exception
Traceback (most recent call last):
  File "/home/airflow/.local/lib/python3.7/site-packages/airflow/operators/python.py", line 171, in execute
    return_value = self.execute_callable()
  File "/home/airflow/.local/lib/python3.7/site-packages/airflow/operators/python.py", line 189, in execute_callable
    return self.python_callable(*self.op_args, **self.op_kwargs)
  File "/opt/airflow/dags/myETL.py", line 51, in get_and_transform_data
    data = ti.xcom_pull(key='api_call', task_ids=['api_call'])
TypeError: xcom_pull() missing 1 required positional argument: 'context'
[2023-08-21 20:52:08,045] {taskinstance.py:1420} INFO - Marking task as UP_FOR_RETRY. dag_id=Products_ETL_v2, task_id=get_data, execution_date=20230820T000000, start_date=20230821T205206, end_date=20230821T205208
[2023-08-21 20:52:08,081] {standard_task_runner.py:97} ERROR - Failed to execute job 71 for task get_data (xcom_pull() missing 1 required positional argument: 'context'; 13188)
[2023-08-21 20:52:08,139] {local_task_job.py:156} INFO - Task exited with return code 1
[2023-08-21 20:52:08,293] {local_task_job.py:273} INFO - 0 downstream tasks scheduled from follow-on schedule check
