[2023-08-22 13:41:15,473] {taskinstance.py:1179} INFO - Dependencies all met for <TaskInstance: new_etl.extraer_data manual__2023-08-22T13:32:04.097181+00:00 [queued]>
[2023-08-22 13:41:15,484] {taskinstance.py:1179} INFO - Dependencies all met for <TaskInstance: new_etl.extraer_data manual__2023-08-22T13:32:04.097181+00:00 [queued]>
[2023-08-22 13:41:15,484] {taskinstance.py:1376} INFO - 
--------------------------------------------------------------------------------
[2023-08-22 13:41:15,485] {taskinstance.py:1377} INFO - Starting attempt 4 of 4
[2023-08-22 13:41:15,486] {taskinstance.py:1378} INFO - 
--------------------------------------------------------------------------------
[2023-08-22 13:41:15,496] {taskinstance.py:1397} INFO - Executing <Task(PythonOperator): extraer_data> on 2023-08-22 13:32:04.097181+00:00
[2023-08-22 13:41:15,505] {standard_task_runner.py:52} INFO - Started process 760 to run task
[2023-08-22 13:41:15,509] {standard_task_runner.py:79} INFO - Running: ['***', 'tasks', 'run', 'new_etl', 'extraer_data', 'manual__2023-08-22T13:32:04.097181+00:00', '--job-id', '135', '--raw', '--subdir', 'DAGS_FOLDER/etl2.py', '--cfg-path', '/tmp/tmpp0fhguoj', '--error-file', '/tmp/tmpd66if71r']
[2023-08-22 13:41:15,510] {standard_task_runner.py:80} INFO - Job 135: Subtask extraer_data
[2023-08-22 13:41:15,583] {task_command.py:371} INFO - Running <TaskInstance: new_etl.extraer_data manual__2023-08-22T13:32:04.097181+00:00 [running]> on host 0110d0e687e9
[2023-08-22 13:41:15,683] {taskinstance.py:1591} INFO - Exporting the following env vars:
AIRFLOW_CTX_DAG_OWNER=Sol
AIRFLOW_CTX_DAG_ID=new_etl
AIRFLOW_CTX_TASK_ID=extraer_data
AIRFLOW_CTX_EXECUTION_DATE=2023-08-22T13:32:04.097181+00:00
AIRFLOW_CTX_TRY_NUMBER=4
AIRFLOW_CTX_DAG_RUN_ID=manual__2023-08-22T13:32:04.097181+00:00
[2023-08-22 13:41:18,023] {taskinstance.py:1909} ERROR - Task failed with exception
Traceback (most recent call last):
  File "/home/airflow/.local/lib/python3.7/site-packages/airflow/operators/python.py", line 171, in execute
    return_value = self.execute_callable()
  File "/home/airflow/.local/lib/python3.7/site-packages/airflow/operators/python.py", line 189, in execute_callable
    return self.python_callable(*self.op_args, **self.op_kwargs)
  File "/opt/airflow/dags/function_etl.py", line 43, in extraer_data
    with open(dag_path+'/raw_data/'+"data.json", "w") as json_file:
FileNotFoundError: [Errno 2] No such file or directory: '/opt/airflow/raw_data/data.json'
[2023-08-22 13:41:18,080] {taskinstance.py:1420} INFO - Marking task as FAILED. dag_id=new_etl, task_id=extraer_data, execution_date=20230822T133204, start_date=20230822T134115, end_date=20230822T134118
[2023-08-22 13:41:18,119] {standard_task_runner.py:97} ERROR - Failed to execute job 135 for task extraer_data ([Errno 2] No such file or directory: '/opt/airflow/raw_data/data.json'; 760)
[2023-08-22 13:41:18,179] {local_task_job.py:156} INFO - Task exited with return code 1
[2023-08-22 13:41:18,250] {local_task_job.py:273} INFO - 0 downstream tasks scheduled from follow-on schedule check
