[2023-08-22 14:05:54,152] {taskinstance.py:1179} INFO - Dependencies all met for <TaskInstance: new_etl.transformar_data manual__2023-08-22T14:02:46.671358+00:00 [queued]>
[2023-08-22 14:05:54,160] {taskinstance.py:1179} INFO - Dependencies all met for <TaskInstance: new_etl.transformar_data manual__2023-08-22T14:02:46.671358+00:00 [queued]>
[2023-08-22 14:05:54,161] {taskinstance.py:1376} INFO - 
--------------------------------------------------------------------------------
[2023-08-22 14:05:54,162] {taskinstance.py:1377} INFO - Starting attempt 2 of 4
[2023-08-22 14:05:54,162] {taskinstance.py:1378} INFO - 
--------------------------------------------------------------------------------
[2023-08-22 14:05:54,173] {taskinstance.py:1397} INFO - Executing <Task(PythonOperator): transformar_data> on 2023-08-22 14:02:46.671358+00:00
[2023-08-22 14:05:54,180] {standard_task_runner.py:52} INFO - Started process 3869 to run task
[2023-08-22 14:05:54,184] {standard_task_runner.py:79} INFO - Running: ['***', 'tasks', 'run', 'new_etl', 'transformar_data', 'manual__2023-08-22T14:02:46.671358+00:00', '--job-id', '139', '--raw', '--subdir', 'DAGS_FOLDER/etl2.py', '--cfg-path', '/tmp/tmplb6hke5a', '--error-file', '/tmp/tmpxeszix0u']
[2023-08-22 14:05:54,186] {standard_task_runner.py:80} INFO - Job 139: Subtask transformar_data
[2023-08-22 14:05:54,248] {task_command.py:371} INFO - Running <TaskInstance: new_etl.transformar_data manual__2023-08-22T14:02:46.671358+00:00 [running]> on host 0110d0e687e9
[2023-08-22 14:05:54,309] {taskinstance.py:1591} INFO - Exporting the following env vars:
AIRFLOW_CTX_DAG_OWNER=Sol
AIRFLOW_CTX_DAG_ID=new_etl
AIRFLOW_CTX_TASK_ID=transformar_data
AIRFLOW_CTX_EXECUTION_DATE=2023-08-22T14:02:46.671358+00:00
AIRFLOW_CTX_TRY_NUMBER=2
AIRFLOW_CTX_DAG_RUN_ID=manual__2023-08-22T14:02:46.671358+00:00
[2023-08-22 14:05:54,311] {taskinstance.py:1909} ERROR - Task failed with exception
Traceback (most recent call last):
  File "/home/airflow/.local/lib/python3.7/site-packages/airflow/operators/python.py", line 171, in execute
    return_value = self.execute_callable()
  File "/home/airflow/.local/lib/python3.7/site-packages/airflow/operators/python.py", line 189, in execute_callable
    return self.python_callable(*self.op_args, **self.op_kwargs)
  File "/opt/airflow/dags/function_etl.py", line 52, in transformar_data
    df=pd.json_normalize(loaded_data, max_level=1, sep='_')
  File "/home/airflow/.local/lib/python3.7/site-packages/pandas/io/json/_normalize.py", line 438, in _json_normalize
    if any([isinstance(x, dict) for x in y.values()] for y in data):
  File "/home/airflow/.local/lib/python3.7/site-packages/pandas/io/json/_normalize.py", line 438, in <genexpr>
    if any([isinstance(x, dict) for x in y.values()] for y in data):
AttributeError: 'list' object has no attribute 'values'
[2023-08-22 14:05:54,320] {taskinstance.py:1420} INFO - Marking task as UP_FOR_RETRY. dag_id=new_etl, task_id=transformar_data, execution_date=20230822T140246, start_date=20230822T140554, end_date=20230822T140554
[2023-08-22 14:05:54,327] {standard_task_runner.py:97} ERROR - Failed to execute job 139 for task transformar_data ('list' object has no attribute 'values'; 3869)
[2023-08-22 14:05:54,359] {local_task_job.py:156} INFO - Task exited with return code 1
[2023-08-22 14:05:54,391] {local_task_job.py:273} INFO - 0 downstream tasks scheduled from follow-on schedule check
