[2023-08-22 14:20:45,981] {taskinstance.py:1179} INFO - Dependencies all met for <TaskInstance: new_etl.extraer_data manual__2023-08-22T14:17:41.635426+00:00 [queued]>
[2023-08-22 14:20:45,992] {taskinstance.py:1179} INFO - Dependencies all met for <TaskInstance: new_etl.extraer_data manual__2023-08-22T14:17:41.635426+00:00 [queued]>
[2023-08-22 14:20:45,993] {taskinstance.py:1376} INFO - 
--------------------------------------------------------------------------------
[2023-08-22 14:20:45,994] {taskinstance.py:1377} INFO - Starting attempt 2 of 4
[2023-08-22 14:20:45,994] {taskinstance.py:1378} INFO - 
--------------------------------------------------------------------------------
[2023-08-22 14:20:46,006] {taskinstance.py:1397} INFO - Executing <Task(PythonOperator): extraer_data> on 2023-08-22 14:17:41.635426+00:00
[2023-08-22 14:20:46,014] {standard_task_runner.py:52} INFO - Started process 5744 to run task
[2023-08-22 14:20:46,017] {standard_task_runner.py:79} INFO - Running: ['***', 'tasks', 'run', 'new_etl', 'extraer_data', 'manual__2023-08-22T14:17:41.635426+00:00', '--job-id', '150', '--raw', '--subdir', 'DAGS_FOLDER/etl2.py', '--cfg-path', '/tmp/tmp9kqw5o2l', '--error-file', '/tmp/tmp4ed6gz9u']
[2023-08-22 14:20:46,019] {standard_task_runner.py:80} INFO - Job 150: Subtask extraer_data
[2023-08-22 14:20:46,083] {task_command.py:371} INFO - Running <TaskInstance: new_etl.extraer_data manual__2023-08-22T14:17:41.635426+00:00 [running]> on host 0110d0e687e9
[2023-08-22 14:20:46,151] {taskinstance.py:1591} INFO - Exporting the following env vars:
AIRFLOW_CTX_DAG_OWNER=Sol
AIRFLOW_CTX_DAG_ID=new_etl
AIRFLOW_CTX_TASK_ID=extraer_data
AIRFLOW_CTX_EXECUTION_DATE=2023-08-22T14:17:41.635426+00:00
AIRFLOW_CTX_TRY_NUMBER=2
AIRFLOW_CTX_DAG_RUN_ID=manual__2023-08-22T14:17:41.635426+00:00
[2023-08-22 14:20:46,960] {taskinstance.py:1909} ERROR - Task failed with exception
Traceback (most recent call last):
  File "/home/airflow/.local/lib/python3.7/site-packages/airflow/operators/python.py", line 171, in execute
    return_value = self.execute_callable()
  File "/home/airflow/.local/lib/python3.7/site-packages/airflow/operators/python.py", line 189, in execute_callable
    return self.python_callable(*self.op_args, **self.op_kwargs)
  File "/opt/airflow/dags/function_etl.py", line 45, in extraer_data
    with open(os.path.join("raw_data","data.json"), "w") as json_file:
FileNotFoundError: [Errno 2] No such file or directory: 'raw_data/data.json'
[2023-08-22 14:20:47,013] {taskinstance.py:1420} INFO - Marking task as UP_FOR_RETRY. dag_id=new_etl, task_id=extraer_data, execution_date=20230822T141741, start_date=20230822T142045, end_date=20230822T142047
[2023-08-22 14:20:47,028] {standard_task_runner.py:97} ERROR - Failed to execute job 150 for task extraer_data ([Errno 2] No such file or directory: 'raw_data/data.json'; 5744)
[2023-08-22 14:20:47,083] {local_task_job.py:156} INFO - Task exited with return code 1
[2023-08-22 14:20:47,123] {local_task_job.py:273} INFO - 0 downstream tasks scheduled from follow-on schedule check
