[2023-08-21 20:52:06,274] {taskinstance.py:1179} INFO - Dependencies all met for <TaskInstance: Products_ETL_v2.get_data manual__2023-08-21T14:42:57.100447+00:00 [queued]>
[2023-08-21 20:52:06,291] {taskinstance.py:1179} INFO - Dependencies all met for <TaskInstance: Products_ETL_v2.get_data manual__2023-08-21T14:42:57.100447+00:00 [queued]>
[2023-08-21 20:52:06,292] {taskinstance.py:1376} INFO - 
--------------------------------------------------------------------------------
[2023-08-21 20:52:06,293] {taskinstance.py:1377} INFO - Starting attempt 5 of 6
[2023-08-21 20:52:06,293] {taskinstance.py:1378} INFO - 
--------------------------------------------------------------------------------
[2023-08-21 20:52:06,310] {taskinstance.py:1397} INFO - Executing <Task(PythonOperator): get_data> on 2023-08-21 14:42:57.100447+00:00
[2023-08-21 20:52:06,347] {standard_task_runner.py:52} INFO - Started process 13186 to run task
[2023-08-21 20:52:06,366] {standard_task_runner.py:79} INFO - Running: ['***', 'tasks', 'run', 'Products_ETL_v2', 'get_data', 'manual__2023-08-21T14:42:57.100447+00:00', '--job-id', '69', '--raw', '--subdir', 'DAGS_FOLDER/myETL.py', '--cfg-path', '/tmp/tmps5ymz58d', '--error-file', '/tmp/tmp55yr5wda']
[2023-08-21 20:52:06,380] {standard_task_runner.py:80} INFO - Job 69: Subtask get_data
[2023-08-21 20:52:06,834] {task_command.py:371} INFO - Running <TaskInstance: Products_ETL_v2.get_data manual__2023-08-21T14:42:57.100447+00:00 [running]> on host 0110d0e687e9
[2023-08-21 20:52:07,427] {taskinstance.py:1591} INFO - Exporting the following env vars:
AIRFLOW_CTX_DAG_OWNER=Sol
AIRFLOW_CTX_DAG_ID=Products_ETL_v2
AIRFLOW_CTX_TASK_ID=get_data
AIRFLOW_CTX_EXECUTION_DATE=2023-08-21T14:42:57.100447+00:00
AIRFLOW_CTX_TRY_NUMBER=5
AIRFLOW_CTX_DAG_RUN_ID=manual__2023-08-21T14:42:57.100447+00:00
[2023-08-21 20:52:07,438] {taskinstance.py:1909} ERROR - Task failed with exception
Traceback (most recent call last):
  File "/home/airflow/.local/lib/python3.7/site-packages/airflow/operators/python.py", line 171, in execute
    return_value = self.execute_callable()
  File "/home/airflow/.local/lib/python3.7/site-packages/airflow/operators/python.py", line 189, in execute_callable
    return self.python_callable(*self.op_args, **self.op_kwargs)
  File "/opt/airflow/dags/myETL.py", line 51, in get_and_transform_data
    data = ti.xcom_pull(key='api_call', task_ids=['api_call'])
TypeError: xcom_pull() missing 1 required positional argument: 'context'
[2023-08-21 20:52:07,529] {taskinstance.py:1420} INFO - Marking task as UP_FOR_RETRY. dag_id=Products_ETL_v2, task_id=get_data, execution_date=20230821T144257, start_date=20230821T205206, end_date=20230821T205207
[2023-08-21 20:52:07,562] {standard_task_runner.py:97} ERROR - Failed to execute job 69 for task get_data (xcom_pull() missing 1 required positional argument: 'context'; 13186)
[2023-08-21 20:52:07,618] {local_task_job.py:156} INFO - Task exited with return code 1
[2023-08-21 20:52:07,806] {local_task_job.py:273} INFO - 0 downstream tasks scheduled from follow-on schedule check
